{
  "comments": [
    {
      "key": {
        "uuid": "9a3d3df0_6d57f2ca",
        "filename": "openstack/net-virt-sfc/it/src/test/java/org/opendaylight/ovsdb/openstack/netvirt/sfc/it/NetvirtSfcIT.java",
        "patchSetId": 2
      },
      "lineNbr": 346,
      "author": {
        "id": 773
      },
      "writtenOn": "2016-02-19T13:16:38Z",
      "side": 1,
      "message": "does fail() require the \": \" at the end? So that it is different than the LOG where it drops the exception onto the next line?",
      "revId": "1c2ffcc0b97fda099d0e3fc9ad2e14856feeb4c5",
      "serverId": "7fc14799-209e-464c-9743-7a06c2c21a81",
      "unresolved": false
    }
  ]
}